## 예외처리문
 - throw문
 - try...catch문

### throw문
여러분은 구체적 유형의 표현이 아니라도 어떤 표현이든지 사용할 것입니다. 다음 코드는 다양한 유형중의 여러 예외들을 사용합니다:
```js
throw "Error2";   // String type
throw 42;         // Number type
throw true;       // Boolean type
throw {toString: function() { return "I'm an object!"; } };
```

우리만의 객체를 만들어서 사용할 수도 있음
```js
// Create an object type UserException
function UserException (message){
  this.message=message;
  this.name="UserException";
}

// Make the exception convert to a pretty string when used as a string 
// (e.g. by the error console)
UserException.prototype.toString = function () {
  return this.name + ': "' + this.message + '"';
}

// Create an instance of the object type and throw it
throw new UserException("Value too high");
```

### try...catch문
```js
function getMonthName (mo) {
  mo = mo-1; // Adjust month number for array index (1=Jan, 12=Dec)
  var months = ["Jan","Feb","Mar","Apr","May","Jun","Jul",
                "Aug","Sep","Oct","Nov","Dec"];
  if (months[mo] != null) {
    return months[mo];
  } else {
    throw "InvalidMonthNo"; //throw keyword is used here
  }
}

try { // statements to try
  monthName = getMonthName(13); // function could throw exception
}
catch (e) {
  monthName = "unknown";
  console.log(e); // pass exception object to error handler
}
```
 - 만약 finally 블록이 값을 반환하였을 경우, try 블록과 catch블록의 return 문장과 상관없이 전체 try-catch-finally 생산물의 반환값이 됩니다:

```js
function f() {
  try {
    console.log(0);
    throw "bogus";
  } catch(e) {
    console.log(1);
    return true; // this return statement is suspended
                 // until finally block has completed
    console.log(2); // not reachable
  } finally {
    console.log(3);
    return false; // overwrites the previous "return"
    console.log(4); // not reachable
  }
  // "return false" is executed now  
  console.log(5); // not reachable
}
f(); // alerts 0, 1, 3; returns false
```